<?xml version="1.0" ?>
<!-- =================================================================================== -->
<!-- |    This document was autogenerated by xacro from ros2_mara_ws/src/robotiq_modular_gripper/robotiq_hande_gripper_description/urdf/robotiq_hande_world.urdf.xacro | -->
<!-- |    EDITING THIS FILE BY HAND IS NOT RECOMMENDED                                 | -->
<!-- =================================================================================== -->
<robot name="robotiq_hande" xmlns:xacro="http://ros.org/wiki/xacro">
  <link name="hande_robotiq_hande_base_link">
    <inertial>
      <origin rpy="0 0 0" xyz="0 0 0.04607"/>
      <mass value="0.86387"/>
      <inertia ixx="1017560E-9" ixy="0" ixz="2235E-9" iyy="1028041E-9" iyz="0" izz="489810E-9"/>
    </inertial>
    <visual>
      <origin rpy="0 0 0" xyz="0 0 0"/>
      <geometry>
        <mesh filename="package://robotiq_description/meshes/visual/hand-e.dae" scale="0.001 0.001 0.001"/>
      </geometry>
      <material name="Gazebo/Black">
        <color rgba="0.1 0.1 0.1 1"/>
      </material>
    </visual>
    <collision>
      <origin rpy="0 0 0" xyz="0 0 0"/>
      <geometry>
        <mesh filename="package://robotiq_description/meshes/visual/hand-e.dae" scale="0.001 0.001 0.001"/>
      </geometry>
    </collision>
  </link>
  <gazebo reference="hande_robotiq_hande_base_link">
    <material>Gazebo/Black</material>
    <selfCollide>True</selfCollide>
  </gazebo>
  <link name="hande_left_finger">
    <inertial>
      <origin rpy="0 0 0" xyz="0.02262 -0.00759 0.00738"/>
      <mass value="0.03804"/>
      <inertia ixx="13567E-9" ixy="1849E-9" ixz="3622E-9" iyy="15784E-9" iyz="3616E-9" izz="7478E-9"/>
    </inertial>
    <visual>
      <origin rpy="0 0 0" xyz="0 0 0"/>
      <geometry>
        <mesh filename="package://robotiq_description/meshes/visual/hand-e_finger_1.dae" scale="0.001 0.001 0.001"/>
      </geometry>
      <material name="Gazebo/Grey">
        <color rgba="0.1 0.1 0.1 1"/>
      </material>
    </visual>
    <collision>
      <origin rpy="0 0 0" xyz="0 0 0"/>
      <geometry>
        <mesh filename="package://robotiq_description/meshes/visual/hand-e_finger_1.dae" scale="0.001 0.001 0.001"/>
      </geometry>
    </collision>
  </link>
  <gazebo reference="hande_left_finger">
    <material>Gazebo/Grey</material>
    <selfCollide>True</selfCollide>
  </gazebo>
  <link name="hande_right_finger">
    <inertial>
      <origin rpy="0 0 0" xyz="-0.02262 0.00759 0.00738"/>
      <mass value="0.03804"/>
      <inertia ixx="13567E-9" ixy="1849E-9" ixz="-3622E-9" iyy="15784E-9" iyz="-3616E-9" izz="7478E-9"/>
    </inertial>
    <visual>
      <origin rpy="0 0 0" xyz="0 0 0"/>
      <geometry>
        <mesh filename="package://robotiq_description/meshes/visual/hand-e_finger_2.dae" scale="0.001 0.001 0.001"/>
      </geometry>
      <material name="Gazebo/Grey">
        <color rgba="0.1 0.1 0.1 1"/>
      </material>
    </visual>
    <collision>
      <origin rpy="0 0 0" xyz="0 0 0"/>
      <geometry>
        <mesh filename="package://robotiq_description/meshes/visual/hand-e_finger_2.dae" scale="0.001 0.001 0.001"/>
      </geometry>
    </collision>
  </link>
  <gazebo reference="hande_right_finger">
    <material>Gazebo/Grey</material>
    <selfCollide>True</selfCollide>
  </gazebo>
  <joint name="hande_joint_finger" type="prismatic">
    <origin rpy="0 0 0" xyz="0 0 0.099"/>
    <parent link="hande_robotiq_hande_base_link"/>
    <child link="hande_left_finger"/>
    <axis xyz="-1 0 0"/>
    <limit effort="130" lower="0" upper="0.025" velocity="0.15"/>
  </joint>
  <joint name="robotiq_hande_base_to_hande_right_finger" type="prismatic">
    <origin rpy="0 0 0" xyz="0 0 0.099"/>
    <parent link="hande_robotiq_hande_base_link"/>
    <child link="hande_right_finger"/>
    <axis xyz="1 0 0"/>
    <limit effort="130" lower="0" upper="0.025" velocity="0.15"/>
    <mimic joint="hande_joint_finger" multiplier="1" offset="0"/>
  </joint>
  <gazebo>
    <plugin filename="librobotiq_gripper_gazebo_plugin.so" name="hrim_actuator_gripper_000000000004">
      <kp>500</kp>
      <ki>3</ki>
      <kd>9</kd>
      <min_velocity>20</min_velocity>
      <max_velocity>150</max_velocity>
      <joint>hande_joint_finger</joint>
      <joint>robotiq_hande_base_to_hande_right_finger</joint>
    </plugin>
  </gazebo>
  <link name="world"/>
  <joint name="world_to_robotiq_adapter" type="fixed">
    <origin rpy="0 0 0" xyz="0 0 0.5"/>
    <parent link="world"/>
    <child link="hande_robotiq_hande_base_link"/>
  </joint>
  <gazebo>
    <plugin filename="libgazebo_ros_joint_state_publisher.so" name="hande_joint_state">
      <ros>
        <argument>~/out:=hande_joint_states</argument>
      </ros>
      <update_rate>25</update_rate>
      <joint_name>hande_joint_finger</joint_name>
    </plugin>
  </gazebo>
</robot>
